<?xml version="1.0"?>
<robot name="robot" xmlns:xacro="http://ros.org/wiki/xacro">

  <xacro:property name="h" value="0.4" />
  <xacro:property name="rad" value="0.2" />
  <material name="blue">
    <color rgba="0 0 0.8 1"/>
  </material>

  <material name="white">
    <color rgba="1 1 1 1"/>
  </material>

  <xacro:macro name="wheeel" params="mass">
    <inertial>
      <mass value="${mass}" />
      <inertia ixx="0.28" ixy="0.0" ixz="0.0" iyy="0.28" iyz="0.0" izz="0.005" />
    </inertial>
  </xacro:macro>

  <xacro:macro name="basse" params="mass">
    <inertial>
      <mass value="${mass}" />
      <inertia ixx="6.19" ixy="0.0" ixz="0.0" iyy="7.03" iyz="0.0" izz="2.47" />
    </inertial>
  </xacro:macro>

  <link name="world">
  </link>
  <joint name="world_to_base" type="fixed">
    <parent link="world"/>
    <child link="base_link"/>
    <origin rpy="0 0 0" xyz="0 0 0"/>
  </joint>
  <link name="base_link">
    <visual>
      <geometry>
        <box size="1.0 1.8 0.7"/>
      </geometry>
      <origin rpy="0 0 0" xyz="0 0 0.75"/>
      <material name="blue"/>
    </visual>
    <collision>
      <geometry>
        <box size="1.0 1.8 0.7"/>
      </geometry>
    </collision>
    <xacro:basse mass="0.25"/>
  </link>
  <gazebo reference="base_link">
    <material>Gazebo/White</material>
  </gazebo>
  <link name="right_back_wheel">
    <visual>
      <geometry>
        <cylinder length="${h}" radius="${rad}"/>
      </geometry>
      <origin rpy="0 1.5708 0" xyz="0 0 0"/>
      <material name="white"/>
    </visual>
    <collision>
      <geometry>
        <cylinder length="${h}" radius="${rad}"/>
      </geometry>
    </collision>
   <xacro:wheeel mass="0.25"/>
  </link>
  <gazebo reference="right_back_wheel">
    <material>Gazebo/Blue</material>
  </gazebo>

  <joint name="base_to_right_back_wheel" type="continuous">
    <axis rpy="0 0 0" xyz="1 0 0"/>
    <parent link="base_link"/>
    <child link="right_back_wheel"/>
    <origin rpy="0 0 0" xyz="-0.43 0.83 0.2"/>
  </joint>

  <link name="right_front_wheel">
    <visual>
      <geometry>
        <cylinder length="${h}" radius="${rad}"/>
      </geometry>
      <origin rpy="0 1.5708 0" xyz="0 0 0"/>
      <material name="white"/>
    </visual>
    <collision>
      <geometry>
        <cylinder length="${h}" radius="${rad}"/>
      </geometry>
    </collision>
    <xacro:wheeel mass="0.25"/>
  </link>
  <gazebo reference="right_front_wheel">
    <material>Gazebo/Blue</material>
  </gazebo>

  <joint name="base_to_right_front_wheel" type="continuous">
    <axis rpy="0 0 0" xyz="1 0 0"/>
    <parent link="base_link"/>
    <child link="right_front_wheel"/>
    <origin rpy="0 0 0" xyz="0.43 0.83 0.2"/>
  </joint>

  <link name="left_back_wheel">
    <visual>
      <geometry>
        <cylinder length="${h}" radius="${rad}"/>
      </geometry>
      <origin rpy="0 1.5708 0" xyz="0 0 0"/>
      <material name="white"/>
    </visual>
    <collision>
      <geometry>
        <cylinder length="${h}" radius="${rad}"/>
      </geometry>
    </collision>
    <xacro:wheeel mass="0.25"/>
  </link>
  <gazebo reference="left_back_wheel">
    <material>Gazebo/Blue</material>
  </gazebo>

  <joint name="base_to_left_back_wheel" type="continuous">
    <axis rpy="0 0 0" xyz="1 0 0"/>
    <parent link="base_link"/>
    <child link="left_back_wheel"/>
    <origin rpy="0 0 0" xyz="-0.43 -0.83 0.2"/>
  </joint>

  <link name="left_front_wheel">
    <visual>
      <geometry>
        <cylinder length="${h}" radius="${rad}"/>
      </geometry>
      <origin rpy="0 1.5708 0" xyz="0 0 0"/>
      <material name="white"/>
    </visual>
    <collision>
      <geometry>
        <cylinder length="${h}" radius="${rad}"/>
      </geometry>
    </collision>
    <xacro:wheeel mass="0.25"/>
  </link>
  <gazebo reference="left_front_wheel">
    <material>Gazebo/Blue</material>
  </gazebo>

  <joint name="base_to_left_front_wheel" type="continuous">
    <axis rpy="0 0 1" xyz="1 0 0"/>
    <parent link="base_link"/>
    <child link="left_front_wheel"/>
    <origin rpy="0 0 0" xyz="0.43 -0.83 0.2"/>
  </joint>

</robot>
