<?xml version="1.0"?>
<robot name="myfirst">

  <material name="blue">
    <color rgba="0 0 0.8 1"/>
  </material>

  <material name="white">
    <color rgba="1 1 1 1"/>
  </material>

  <link name="world">
  </link>
  <joint name="world_to_base" type="fixed">
    <parent link="world"/>
    <child link="base_link"/>
    <origin rpy="0 0 0" xyz="0 0 0"/>
  </joint>
  <link name="base_link">
    <visual>
      <geometry>
        <box size="1.0 1.8 0.7"/>
      </geometry>
      <origin rpy="0 0 0" xyz="0 0 0.75"/>
      <material name="blue"/>
    </visual>
    <collision>
      <geometry>
        <box size="1.0 1.8 0.7"/>
      </geometry>
    </collision>
  </link>
  <link name="right_back_wheel">
    <visual>
      <geometry>
        <cylinder length="0.4" radius="0.2"/>
      </geometry>
      <origin rpy="0 1.5708 0" xyz="0 0 0"/>
      <material name="white"/>
    </visual>
    <collision>
      <geometry>
        <cylinder length="0.4" radius="0.2"/>
      </geometry>
    </collision>
  </link>

  <joint name="base_to_right_back_wheel" type="continuous">
    <axis rpy="0 0 0" xyz="1 0 0"/>
    <parent link="base_link"/>
    <child link="right_back_wheel"/>
    <origin rpy="0 0 0" xyz="-0.43 0.83 0.2"/>
  </joint>

  <link name="right_front_wheel">
    <visual>
      <geometry>
        <cylinder length="0.4" radius="0.2"/>
      </geometry>
      <origin rpy="0 1.5708 0" xyz="0 0 0"/>
      <material name="white"/>
    </visual>
    <collision>
      <geometry>
        <cylinder length="0.4" radius="0.2"/>
      </geometry>
    </collision>
  </link>

  <joint name="base_to_right_front_wheel" type="continuous">
    <axis rpy="0 0 0" xyz="1 0 0"/>
    <parent link="base_link"/>
    <child link="right_front_wheel"/>
    <origin rpy="0 0 0" xyz="0.43 0.83 0.2"/>
  </joint>

  <link name="left_back_wheel">
    <visual>
      <geometry>
        <cylinder length="0.4" radius="0.2"/>
      </geometry>
      <origin rpy="0 1.5708 0" xyz="0 0 0"/>
      <material name="white"/>
    </visual>
    <collision>
      <geometry>
        <cylinder length="0.4" radius="0.2"/>
      </geometry>
    </collision>
  </link>

  <joint name="base_to_left_back_wheel" type="continuous">
    <axis rpy="0 0 0" xyz="1 0 0"/>
    <parent link="base_link"/>
    <child link="left_back_wheel"/>
    <origin rpy="0 0 0" xyz="-0.43 -0.83 0.2"/>
  </joint>

  <link name="left_front_wheel">
    <visual>
      <geometry>
        <cylinder length="0.4" radius="0.2"/>
      </geometry>
      <origin rpy="0 1.5708 0" xyz="0 0 0"/>
      <material name="white"/>
    </visual>
    <collision>
      <geometry>
        <cylinder length="0.4" radius="0.2"/>
      </geometry>
    </collision>
  </link>

  <joint name="base_to_left_front_wheel" type="continuous">
    <axis rpy="0 0 1" xyz="1 0 0"/>
    <parent link="base_link"/>
    <child link="left_front_wheel"/>
    <origin rpy="0 0 0" xyz="0.43 -0.83 0.2"/>
  </joint>
</robot>
